<?xml version="1.0"?>
<robot name="ipr_worlds/controllers/ipr_cube_python/IprHd6m180.urdf" xmlns:xacro="http://ros.org/wiki/xacro">
  <link name="base_link">
    <visual>
      <origin xyz="0 0 0.007" rpy="0 0 0"/>
      <geometry>
        <cylinder radius="0.055" length="0.014"/>
      </geometry>
    </visual>
    <collision>
      <origin xyz="0 0 0.007" rpy="0 0 0"/>
      <geometry>
        <cylinder radius="0.055" length="0.014"/>
      </geometry>
    </collision>
    <visual>
      <origin xyz="0 0 0.029" rpy="0 0 0"/>
      <geometry>
        <cylinder radius="0.046" length="0.03"/>
      </geometry>
    </visual>
    <collision>
      <origin xyz="0 0 0.029" rpy="0 0 0"/>
      <geometry>
        <cylinder radius="0.046" length="0.03"/>
      </geometry>
    </collision>
    <visual>
      <origin xyz="0 0 0.049" rpy="0 0 0"/>
      <geometry>
        <cylinder radius="0.042" length="0.01"/>
      </geometry>
    </visual>
    <collision>
      <origin xyz="0 0 0.049" rpy="0 0 0"/>
      <geometry>
        <cylinder radius="0.042" length="0.01"/>
      </geometry>
    </collision>
    <visual>
      <origin xyz="0 0 0.086" rpy="0 0 0"/>
      <geometry>
        <cylinder radius="0.0385" length="0.064"/>
      </geometry>
    </visual>
    <collision>
      <origin xyz="0 0 0.086" rpy="0 0 0"/>
      <geometry>
        <cylinder radius="0.0385" length="0.064"/>
      </geometry>
    </collision>
    <visual>
      <origin xyz="0 0 0.1295" rpy="0 0 0"/>
      <geometry>
        <cylinder radius="0.041" length="0.023"/>
      </geometry>
    </visual>
    <collision>
      <origin xyz="0 0 0.1295" rpy="0 0 0"/>
      <geometry>
        <cylinder radius="0.041" length="0.023"/>
      </geometry>
    </collision>
  </link>
  <joint name="base" type="revolute">
    <parent link="base_link"/>
    <child link="base"/>
    <axis xyz="0 0 1"/>
    <limit effort="20" lower="0" upper="6.0335" velocity="2.20894"/>
    <origin xyz="0 0 0.2035" rpy="0 0 2.160746"/>
  </joint>
  <link name="base">
    <visual>
      <origin xyz="0 0 0.001" rpy="0 -1.57 0"/>
      <geometry>
        <cylinder radius="0.046" length="0.103"/>
      </geometry>
    </visual>
    <collision>
      <origin xyz="0 0 0.001" rpy="0 -1.57 0"/>
      <geometry>
        <cylinder radius="0.046" length="0.103"/>
      </geometry>
    </collision>
    <visual>
      <origin xyz="0 0 -0.031" rpy="0 0 0"/>
      <geometry>
        <box size="0.103 0.092 0.061"/>
      </geometry>
    </visual>
    <collision>
      <origin xyz="0 0 -0.031" rpy="0 0 0"/>
      <geometry>
        <box size="0.103 0.092 0.061"/>
      </geometry>
    </collision>
    <visual>
      <origin xyz="0 0 0" rpy="0 0 0"/>
      <geometry>
        <box size="0.117 0.054 0.054"/>
      </geometry>
    </visual>
    <collision>
      <origin xyz="0 0 0" rpy="0 0 0"/>
      <geometry>
        <box size="0.117 0.054 0.054"/>
      </geometry>
    </collision>
    <visual>
      <origin xyz="0 0 0" rpy="0 -1.57 0"/>
      <geometry>
        <cylinder radius="0.029" length="0.134"/>
      </geometry>
    </visual>
    <collision>
      <origin xyz="0 0 0" rpy="0 -1.57 0"/>
      <geometry>
        <cylinder radius="0.029" length="0.134"/>
      </geometry>
    </collision>
  </link>
  <joint name="upperarm" type="revolute">
    <parent link="base"/>
    <child link="solid"/>
    <axis xyz="-1 0 0"/>
    <limit effort="20" lower="-2.44342" upper="0" velocity="1.1908"/>
    <origin xyz="0 0 0" rpy="0.151362 0 0"/>
  </joint>
  <link name="solid">
    <visual>
      <origin xyz="0 0 0.095" rpy="0 0 0"/>
      <geometry>
        <cylinder radius="0.017" length="0.192"/>
      </geometry>
    </visual>
    <collision>
      <origin xyz="0 0 0.095" rpy="0 0 0"/>
      <geometry>
        <cylinder radius="0.017" length="0.192"/>
      </geometry>
    </collision>
  </link>
  <joint name="forearm" type="revolute">
    <parent link="solid"/>
    <child link="solid_0"/>
    <axis xyz="-1 0 0"/>
    <limit effort="20" lower="0" upper="4.2149" velocity="1.38927"/>
    <origin xyz="0 0 0.19" rpy="1.024432 0 0"/>
  </joint>
  <link name="solid_0">
    <visual>
      <origin xyz="0 0 0" rpy="0 -1.57 0"/>
      <geometry>
        <cylinder radius="0.029" length="0.1265"/>
      </geometry>
    </visual>
    <collision>
      <origin xyz="0 0 0" rpy="0 -1.57 0"/>
      <geometry>
        <cylinder radius="0.029" length="0.1265"/>
      </geometry>
    </collision>
    <visual>
      <origin xyz="0 0 0" rpy="0 -1.57 0"/>
      <geometry>
        <cylinder radius="0.038" length="0.074"/>
      </geometry>
    </visual>
    <collision>
      <origin xyz="0 0 0" rpy="0 -1.57 0"/>
      <geometry>
        <cylinder radius="0.038" length="0.074"/>
      </geometry>
    </collision>
    <visual>
      <origin xyz="0 0 0.021" rpy="0 0 0"/>
      <geometry>
        <box size="0.074 0.073 0.042"/>
      </geometry>
    </visual>
    <collision>
      <origin xyz="0 0 0.021" rpy="0 0 0"/>
      <geometry>
        <box size="0.074 0.073 0.042"/>
      </geometry>
    </collision>
    <visual>
      <origin xyz="0 0 0.042" rpy="0 -1.57 0"/>
      <geometry>
        <cylinder radius="0.035" length="0.074"/>
      </geometry>
    </visual>
    <collision>
      <origin xyz="0 0 0.042" rpy="0 -1.57 0"/>
      <geometry>
        <cylinder radius="0.035" length="0.074"/>
      </geometry>
    </collision>
    <visual>
      <origin xyz="0 0 0.1" rpy="0 0 0"/>
      <geometry>
        <cylinder radius="0.017" length="0.078"/>
      </geometry>
    </visual>
    <collision>
      <origin xyz="0 0 0.1" rpy="0 0 0"/>
      <geometry>
        <cylinder radius="0.017" length="0.078"/>
      </geometry>
    </collision>
  </link>
  <joint name="wrist" type="revolute">
    <parent link="solid_0"/>
    <child link="solid_1"/>
    <axis xyz="-1 0 0"/>
    <limit effort="20" lower="-4.0491" upper="0" velocity="2.20894"/>
    <origin xyz="0 0 0.139" rpy="0.006506 0 0"/>
  </joint>
  <link name="solid_1">
    <visual>
      <origin xyz="0 0 0" rpy="0 -1.57 0"/>
      <geometry>
        <cylinder radius="0.029" length="0.1265"/>
      </geometry>
    </visual>
    <collision>
      <origin xyz="0 0 0" rpy="0 -1.57 0"/>
      <geometry>
        <cylinder radius="0.029" length="0.1265"/>
      </geometry>
    </collision>
    <visual>
      <origin xyz="0 0 0" rpy="0 -1.57 0"/>
      <geometry>
        <cylinder radius="0.038" length="0.074"/>
      </geometry>
    </visual>
    <collision>
      <origin xyz="0 0 0" rpy="0 -1.57 0"/>
      <geometry>
        <cylinder radius="0.038" length="0.074"/>
      </geometry>
    </collision>
    <visual>
      <origin xyz="0 0 0.021" rpy="0 0 0"/>
      <geometry>
        <box size="0.074 0.073 0.042"/>
      </geometry>
    </visual>
    <collision>
      <origin xyz="0 0 0.021" rpy="0 0 0"/>
      <geometry>
        <box size="0.074 0.073 0.042"/>
      </geometry>
    </collision>
    <visual>
      <origin xyz="0 0 0.042" rpy="0 -1.57 0"/>
      <geometry>
        <cylinder radius="0.035" length="0.074"/>
      </geometry>
    </visual>
    <collision>
      <origin xyz="0 0 0.042" rpy="0 -1.57 0"/>
      <geometry>
        <cylinder radius="0.035" length="0.074"/>
      </geometry>
    </collision>
    <visual>
      <origin xyz="0 0 0.086" rpy="0 0 0"/>
      <geometry>
        <cylinder radius="0.03" length="0.065"/>
      </geometry>
    </visual>
    <collision>
      <origin xyz="0 0 0.086" rpy="0 0 0"/>
      <geometry>
        <cylinder radius="0.03" length="0.065"/>
      </geometry>
    </collision>
    <visual>
      <origin xyz="0 0 0.11" rpy="0 0 0"/>
      <geometry>
        <cylinder radius="0.037" length="0.012"/>
      </geometry>
    </visual>
    <collision>
      <origin xyz="0 0 0.11" rpy="0 0 0"/>
      <geometry>
        <cylinder radius="0.037" length="0.012"/>
      </geometry>
    </collision>
  </link>
  <joint name="rotational_wrist" type="revolute">
    <parent link="solid_1"/>
    <child link="solid_2"/>
    <axis xyz="0 0 1"/>
    <limit effort="20" lower="-5.79789" upper="0" velocity="2.20894"/>
    <origin xyz="0 0 0.1185" rpy="0 0 0.962531"/>
  </joint>
  <link name="solid_2">
    <visual>
      <origin xyz="0 0 0.0009" rpy="0 0 0"/>
      <geometry>
        <cylinder radius="0.03" length="0.0018"/>
      </geometry>
    </visual>
    <collision>
      <origin xyz="0 0 0.0009" rpy="0 0 0"/>
      <geometry>
        <cylinder radius="0.03" length="0.0018"/>
      </geometry>
    </collision>
    <visual>
      <origin xyz="0 0 0.03405" rpy="0 0 0"/>
      <geometry>
        <cylinder radius="0.025" length="0.0645"/>
      </geometry>
    </visual>
    <collision>
      <origin xyz="0 0 0.03405" rpy="0 0 0"/>
      <geometry>
        <cylinder radius="0.025" length="0.0645"/>
      </geometry>
    </collision>
    <visual>
      <origin xyz="0 0.0125 0.0318" rpy="-1.57 0 0"/>
      <geometry>
        <cylinder radius="0.025" length="0.025"/>
      </geometry>
    </visual>
    <collision>
      <origin xyz="0 0.0125 0.0318" rpy="-1.57 0 0"/>
      <geometry>
        <cylinder radius="0.025" length="0.025"/>
      </geometry>
    </collision>
    <visual>
      <origin xyz="0 0 0.06855" rpy="0 0 0"/>
      <geometry>
        <cylinder radius="0.0175" length="0.0045"/>
      </geometry>
    </visual>
    <collision>
      <origin xyz="0 0 0.06855" rpy="0 0 0"/>
      <geometry>
        <cylinder radius="0.0175" length="0.0045"/>
      </geometry>
    </collision>
    <visual>
      <origin xyz="0 0 0.0918" rpy="0 0 0"/>
      <geometry>
        <cylinder radius="0.0195" length="0.042"/>
      </geometry>
    </visual>
    <collision>
      <origin xyz="0 0 0.0918" rpy="0 0 0"/>
      <geometry>
        <cylinder radius="0.0195" length="0.042"/>
      </geometry>
    </collision>
    <visual>
      <origin xyz="0 0.032 0.0318" rpy="-1.57 0 0"/>
      <geometry>
        <cylinder radius="0.03" length="0.012"/>
      </geometry>
    </visual>
    <collision>
      <origin xyz="0 0.032 0.0318" rpy="-1.57 0 0"/>
      <geometry>
        <cylinder radius="0.03" length="0.012"/>
      </geometry>
    </collision>
  </link>
  <joint name="gripper::right" type="revolute">
    <parent link="solid_2"/>
    <child link="right_gripper"/>
    <axis xyz="0 -1 0"/>
    <limit effort="20" lower="0" upper="1.22171" velocity="2.20894"/>
    <origin xyz="0 0 0.0983" rpy="0 -0.727475 0"/>
  </joint>
  <link name="right_gripper">
    <visual>
      <origin xyz="-0.018 0 0.064" rpy="0 0.951 0"/>
      <geometry>
        <box size="0.016 0.025 0.029"/>
      </geometry>
    </visual>
    <collision>
      <origin xyz="-0.018 0 0.064" rpy="0 0.951 0"/>
      <geometry>
        <box size="0.016 0.025 0.029"/>
      </geometry>
    </collision>
  </link>
  <link name="ts3">
    <visual>
      <origin xyz="0.0085 0 0" rpy="0 0 0"/>
      <geometry>
        <box size="0.0165 0.025 0.034"/>
      </geometry>
    </visual>
    <collision>
      <origin xyz="0.0085 0 0" rpy="0 0 0"/>
      <geometry>
        <box size="0.0165 0.025 0.034"/>
      </geometry>
    </collision>
  </link>
  <joint name="right_gripper_ts3_joint" type="fixed">
    <parent link="right_gripper"/>
    <child link="ts3"/>
    <origin xyz="0.000103 -0.000018 0.083751" rpy="-3.141593 -0.000093 -3.141593"/>
  </joint>
  <link name="ts2">
    <visual>
      <origin xyz="0.011 0 -0.01" rpy="0 0 0"/>
      <geometry>
        <box size="0.02 0.025 0.049"/>
      </geometry>
    </visual>
    <collision>
      <origin xyz="0.011 0 -0.01" rpy="0 0 0"/>
      <geometry>
        <box size="0.02 0.025 0.049"/>
      </geometry>
    </collision>
  </link>
  <joint name="right_gripper_ts2_joint" type="fixed">
    <parent link="right_gripper"/>
    <child link="ts2"/>
    <origin xyz="-0.007804 0.000005 0.032451" rpy="-3.141593 0.191907 -3.141593"/>
  </joint>
  <link name="ds8">
  </link>
  <joint name="right_gripper_ds8_joint" type="fixed">
    <parent link="right_gripper"/>
    <child link="ds8"/>
    <origin xyz="0 0 0.0988" rpy="-1.57 0 0"/>
  </joint>
  <link name="ds7">
  </link>
  <joint name="right_gripper_ds7_joint" type="fixed">
    <parent link="right_gripper"/>
    <child link="ds7"/>
    <origin xyz="-0.015 0 0.0837" rpy="0 0 -1.57"/>
  </joint>
  <link name="ds6">
  </link>
  <joint name="right_gripper_ds6_joint" type="fixed">
    <parent link="right_gripper"/>
    <child link="ds6"/>
    <origin xyz="0 0 0.0837" rpy="0 0 1.57"/>
  </joint>
  <link name="ds5">
  </link>
  <joint name="right_gripper_ds5_joint" type="fixed">
    <parent link="right_gripper"/>
    <child link="ds5"/>
    <origin xyz="-0.007 0 0.0325" rpy="-0.196641 0.189299 1.532516"/>
  </joint>
  <link name="ds4">
  </link>
  <joint name="solid_2_ds4_joint" type="fixed">
    <parent link="solid_2"/>
    <child link="ds4"/>
    <origin xyz="0 0 0.1128" rpy="-1.57 0 0"/>
  </joint>
  <joint name="gripper::left" type="revolute">
    <parent link="solid_2"/>
    <child link="left_gripper"/>
    <axis xyz="0 1 0"/>
    <limit effort="20" lower="0" upper="1.22171" velocity="2.20894"/>
    <origin xyz="0 0 0.0983" rpy="0 0.727475 0"/>
  </joint>
  <link name="left_gripper">
    <visual>
      <origin xyz="0.018 0 0.064" rpy="0 -0.951 0"/>
      <geometry>
        <box size="0.016 0.025 0.029"/>
      </geometry>
    </visual>
    <collision>
      <origin xyz="0.018 0 0.064" rpy="0 -0.951 0"/>
      <geometry>
        <box size="0.016 0.025 0.029"/>
      </geometry>
    </collision>
  </link>
  <link name="ts1">
    <visual>
      <origin xyz="0.0085 0 0" rpy="0 0 0"/>
      <geometry>
        <box size="0.0165 0.025 0.034"/>
      </geometry>
    </visual>
    <collision>
      <origin xyz="0.0085 0 0" rpy="0 0 0"/>
      <geometry>
        <box size="0.0165 0.025 0.034"/>
      </geometry>
    </collision>
  </link>
  <joint name="left_gripper_ts1_joint" type="fixed">
    <parent link="left_gripper"/>
    <child link="ts1"/>
    <origin xyz="-0.000049 0.000047 0.083905" rpy="0 0 0"/>
  </joint>
  <link name="ts0">
    <visual>
      <origin xyz="0.013 0 0.01" rpy="0 0 0"/>
      <geometry>
        <box size="0.02 0.025 0.049"/>
      </geometry>
    </visual>
    <collision>
      <origin xyz="0.013 0 0.01" rpy="0 0 0"/>
      <geometry>
        <box size="0.02 0.025 0.049"/>
      </geometry>
    </collision>
  </link>
  <joint name="left_gripper_ts0_joint" type="fixed">
    <parent link="left_gripper"/>
    <child link="ts0"/>
    <origin xyz="0.00574 -0.000035 0.032336" rpy="0 0.192 0"/>
  </joint>
  <link name="ds3">
  </link>
  <joint name="left_gripper_ds3_joint" type="fixed">
    <parent link="left_gripper"/>
    <child link="ds3"/>
    <origin xyz="0 0 0.0988" rpy="0 -1.57 0"/>
  </joint>
  <link name="ds2">
  </link>
  <joint name="left_gripper_ds2_joint" type="fixed">
    <parent link="left_gripper"/>
    <child link="ds2"/>
    <origin xyz="0.015 0 0.0837" rpy="1.57 0 0"/>
  </joint>
  <link name="ds1">
  </link>
  <joint name="left_gripper_ds1_joint" type="fixed">
    <parent link="left_gripper"/>
    <child link="ds1"/>
    <origin xyz="0 0 0.0837" rpy="1.570796 0 -3.140796"/>
  </joint>
  <link name="ds0">
  </link>
  <joint name="left_gripper_ds0_joint" type="fixed">
    <parent link="left_gripper"/>
    <child link="ds0"/>
    <origin xyz="0.007 0 0.0325" rpy="1.763724 -0.193083 -3.140781"/>
  </joint>
  <link name="solid_3">
  </link>
  <joint name="solid_2_solid_3_joint" type="fixed">
    <parent link="solid_2"/>
    <child link="solid_3"/>
    <origin xyz="0 0 0" rpy="0 0 0"/>
  </joint>
  <link name="solid_4">
    <visual>
      <origin xyz="0.2225 0.5225 -0.027" rpy="0 0 0"/>
      <geometry>
        <box size="0.6 1.2 0.03"/>
      </geometry>
    </visual>
    <collision>
      <origin xyz="0.2225 0.5225 -0.027" rpy="0 0 0"/>
      <geometry>
        <box size="0.6 1.2 0.03"/>
      </geometry>
    </collision>
    <visual>
      <origin xyz="0.03 0.1 -0.342" rpy="0 0 0"/>
      <geometry>
        <box size="0.05 0.05 0.6"/>
      </geometry>
    </visual>
    <collision>
      <origin xyz="0.03 0.1 -0.342" rpy="0 0 0"/>
      <geometry>
        <box size="0.05 0.05 0.6"/>
      </geometry>
    </collision>
    <visual>
      <origin xyz="0.03 1 -0.342" rpy="0 0 0"/>
      <geometry>
        <box size="0.05 0.05 0.6"/>
      </geometry>
    </visual>
    <collision>
      <origin xyz="0.03 1 -0.342" rpy="0 0 0"/>
      <geometry>
        <box size="0.05 0.05 0.6"/>
      </geometry>
    </collision>
    <visual>
      <origin xyz="0.4 0.1 -0.342" rpy="0 0 0"/>
      <geometry>
        <box size="0.05 0.05 0.6"/>
      </geometry>
    </visual>
    <collision>
      <origin xyz="0.4 0.1 -0.342" rpy="0 0 0"/>
      <geometry>
        <box size="0.05 0.05 0.6"/>
      </geometry>
    </collision>
    <visual>
      <origin xyz="0.4 1 -0.342" rpy="0 0 0"/>
      <geometry>
        <box size="0.05 0.05 0.6"/>
      </geometry>
    </visual>
    <collision>
      <origin xyz="0.4 1 -0.342" rpy="0 0 0"/>
      <geometry>
        <box size="0.05 0.05 0.6"/>
      </geometry>
    </collision>
  </link>
  <joint name="base_link_solid_4_joint" type="fixed">
    <parent link="base_link"/>
    <child link="solid_4"/>
    <origin xyz="0 0 -0.000295" rpy="0 0 0"/>
  </joint>
</robot>
